<?xml version="1.0" ?>
<robot name="edubot" xmlns:xacro="http://ros.org/wiki/xacro">
  <xacro:include filename="$(find edubot_description)/urdf/common_properties.xacro"/>
  <xacro:include filename="$(find edubot_description)/urdf/edubot.gazebo.xacro"/>

  <link name="base_footprint"/>

  <joint name="base_joint" type="fixed">
    <parent link="base_footprint"/>
    <child link="base_link"/>
    <origin xyz="0.0 0.0 0.002" rpy="0 0 0"/>
  </joint>

  <link name="base_link">
    <visual>
      <origin xyz="0 0.0005 0.0" rpy="0 0 0"/>
      <geometry>
        <mesh filename="package://edubot_description/meshes/bases/edubot_base.dae" scale="0.001 0.001 0.001"/>
      </geometry>
    </visual>

    <collision>
      <origin xyz="0.009 0 0.028" rpy="0 0 0"/>
      <geometry>
        <box size="0.053 0.050 0.04"/>
      </geometry>
    </collision>

    <inertial>
      <origin xyz="0 0 0" rpy="0 0 0"/>
      <mass value="8.2573504e-01"/>
      <inertia ixx="2.2124416e-03" ixy="-1.2294101e-05" ixz="3.4938785e-05"
               iyy="2.1193702e-03" iyz="-5.0120904e-06"
               izz="2.0064271e-03" />
    </inertial>
  </link>

  <joint name="wheel_left_joint" type="continuous">
    <parent link="base_link"/>
    <child link="wheel_left_link"/>
    <origin xyz="0.001 0.028 0.0165" rpy="-1.57 0 0"/>
    <axis xyz="0 0 1"/>
  </joint>

  <link name="wheel_left_link">
    <visual>
      <origin xyz="0 0 0" rpy="0 0 0"/>
      <geometry>
        <cylinder length="0.005" radius="0.016"/>
      </geometry>
      <material name="dark"/>
    </visual>

    <collision>
      <origin xyz="0 0 0" rpy="0 0 0"/>
      <geometry>
        <cylinder length="0.005" radius="0.016"/>
      </geometry>
    </collision>

    <inertial>
      <origin xyz="0 0 0" />
      <mass value="2.3498940e-02" />
      <inertia ixx="1.1175580e-05" ixy="-4.2369783e-11" ixz="-5.9381719e-09"
               iyy="1.1192413e-05" iyz="-1.4400107e-11"
               izz="2.0712558e-05" />
      </inertial>
  </link>

  <joint name="wheel_right_joint" type="continuous">
    <parent link="base_link"/>
    <child link="wheel_right_link"/>
    <origin xyz="0.001 -0.028 0.0165" rpy="-1.57 0 0"/>
    <axis xyz="0 0 1"/>
  </joint>

  <link name="wheel_right_link">
    <visual>
      <origin xyz="0 0 0" rpy="0 0 0"/>
      <geometry>
        <cylinder length="0.005" radius="0.016"/>
      </geometry>
      <material name="dark"/>
    </visual>

    <collision>
      <origin xyz="0 0 0" rpy="0 0 0"/>
      <geometry>
        <cylinder length="0.005" radius="0.016"/>
      </geometry>
    </collision>

    <inertial>
      <origin xyz="0 0 0" />
      <mass value="2.3498940e-02" />
      <inertia ixx="1.1175580e-05" ixy="-4.2369783e-11" ixz="-5.9381719e-09"
               iyy="1.1192413e-05" iyz="-1.4400107e-11"
               izz="2.0712558e-05" />
      </inertial>
  </link>

  <joint name="caster_back_joint" type="fixed">
    <parent link="base_link"/>
    <child link="caster_back_link"/>
    <origin xyz="0.03 0 0.0029" rpy="-1.57 0 0"/>
  </joint>

  <link name="caster_back_link">
    <collision>
      <origin xyz="0 0.0 0" rpy="0 0 0"/>
      <geometry>
        <box size="0.01 0.0043 0.01"/>
      </geometry>
    </collision>

    <inertial>
      <origin xyz="0 0 0" />
      <mass value="0.3" />
      <inertia ixx="0.001" ixy="0.0" ixz="0.0"
               iyy="0.001" iyz="0.0"
               izz="0.001" />
    </inertial>
  </link>

  <joint name="imu_joint" type="fixed">
    <parent link="base_link"/>
    <child link="imu_link"/>
    <origin xyz="0 0 0" rpy="0 0 0"/>
  </joint>

  <link name="imu_link"/>

  <joint name="tof_left_joint" type="fixed">
    <parent link="base_link"/>
    <child link="tof_left_link"/>
    <origin xyz="0.036 0.020 0.033" rpy="0 -0.1 0"/>
  </joint>

  <link name="tof_left_link">
  </link>

  <joint name="tof_right_joint" type="fixed">
    <parent link="base_link"/>
    <child link="tof_right_link"/>
    <origin xyz="0.036 -0.020 0.033" rpy="0 -0.1 0"/>
  </joint>

  <link name="tof_right_link">
  </link>

  <joint name="scan_joint" type="fixed">
    <parent link="base_link"/>
    <child link="base_scan"/>
    <origin xyz="0.036 0 0.05" rpy="0 0 0"/>
  </joint>

  <link name="base_scan">
  </link>

  <!--<joint name="face_joint" type="fixed">
    <parent link="base_link"/>
    <child link="face_link"/>
    <origin xyz="0.0541 0 0.027" rpy="0 0 0"/>
  </joint>

  <link name="face_link">
    <visual>
      <origin xyz="0 0 0" rpy="0 0 0"/>
      <geometry>
        <box size="0.001389 0.030255 0.019776"/>
      </geometry>
      <material name="dark"/>
    </visual>
  </link>-->

</robot>
